Workbook

Sheet Dashboard
A1: Trent Ltd - Dashboard
A2: Every figure links into the model: change an input or the scenario switch and this page follows
A4: The call | B4: Value | D4: INR Cr | E4: Mar-26 | F4: Mar-27E | G4: Mar-28E
A5: Rating | B5: =DCF!B60 -> SELL | D5: Revenue | E5: ='Income Statement'!K6 -> 20074.21 | F5: ='Income Statement'!L6 -> 24085.037 | G5: ='Income Statement'!M6 -> 27931.418
A6: Target price (INR) | B6: =DCF!B56 -> 875 | D6: EBITDA | E6: ='Income Statement'!K10 -> 3745.35 | F6: ='Income Statement'!L10 -> 4696.5822 | G6: ='Income Statement'!M10 -> 5530.4207
A7: Current market price (INR) | B7: =DCF!B46 -> 2971 | D7: Profit after tax | E7: ='Income Statement'!K18 -> 1719.65 | F7: ='Income Statement'!L18 -> 2297.5924 | G7: ='Income Statement'!M18 -> 2729.9826
A8: Upside / (downside) to target | B8: =DCF!B57 -> -0.70548637 | D8: EPS (INR) | E8: ='Income Statement'!K19 -> 32.249547 | F8: ='Income Statement'!L19 -> 43.088019 | G8: ='Income Statement'!M19 -> 51.196873
A9: Target basis | B9: =DCF!B50 -> Perpetuity DCF | D9: EBITDA margin | E9: =E6/E5 -> 0.18657521 | F9: =F6/F5 -> 0.195 | G9: =G6/G5 -> 0.198
A10: Target horizon (months) | B10: =DCF!B51 -> 12
A11: Active scenario | B11: =Scenarios!B5 -> Base
A12: Valuation, active scenario | B12: Value
A13: Perpetuity DCF value per share (INR) | B13: =DCF!B45 -> 772.2778
A14: WACC | B14: =DCF!B27 -> 0.1344446
A15: Terminal growth | B15: =DCF!B28 -> 0.06
A16: Return on new capital in perpetuity (RONIC) | B16: =DCF!B29 -> 0.2
A17: Terminal value as % of EV | B17: =DCF!B35 -> 0.58199938
A18: Enterprise value (INR Cr) | B18: =DCF!B34 -> 39462.352
A19: Equity value (INR Cr) | B19: =DCF!B43 -> 41180.347
A21: Value per share by method | B21: INR / share
A22: Base case, perpetuity DCF | B22: =Scenarios!C36 -> 875
A23: Bull case, perpetuity DCF | B23: =Scenarios!C37 -> 1180
A24: Bear case, perpetuity DCF | B24: =Scenarios!C38 -> 545
A25: DCF at the cross-check exit multiple | B25: =DCF!B68 -> 3691.9345
A26: DCF at the alternative exit multiple | B26: =DCF!B70 -> 2424.0568
A27: Current market price | B27: =DCF!B46 -> 2971
A28: Scenario values are recorded when each case is calculated; switch Scenarios!B4 to reproduce one.

Sheet Model info
A1: Trent Ltd - three-statement model
A3: Currency | B3: INR cr
A4: Sector | B4: consumer
A5: History | B5: Mar-17 to Mar-26 (10 years)
A6: Forecast | B6: Mar-27E to Mar-36E (10 years)
A7: Depreciation basis | B7: net_block
A8: Circular solve | B8: 53 passes, residual 0
A9: Checks | B9: ALL PASS
A11: Integrity checks
A12: OK Total assets less total liabilities and equity (forecast) | B12: blocking | C12: 0 | D12: Mar-35E
A13: OK Balance sheet cash less cash flow closing cash (forecast) | B13: blocking | C13: 0 | D13: Mar-36E
A14: OK Reserves roll-forward residual (forecast) | B14: blocking | C14: 0 | D14: Mar-36E
A15: OK Net block roll-forward residual (forecast) | B15: blocking | C15: 0 | D15: Mar-36E
A16: FAIL Reserves roll-forward residual (history) | B16: advisory | C16: 651.64 | D16: Mar-20
A17: OK Net block roll-forward residual (history) | B17: advisory | C17: 0 | D17: Mar-25
A18: FAIL Reconstructed CFO close to reported CFO | B18: advisory | C18: 2370.43 | D18: Mar-21
A19: OK Cash less the minimum cash balance | B19: blocking | C19: 0 | D19: Mar-27E
A20: OK Revolver balance | B20: blocking | C20: 0 | D20: Mar-29E
A21: OK Net block | B21: blocking | C21: 6773.0353 | D21: Mar-27E
A22: OK Shareholders' equity | B22: blocking | C22: 9098.465 | D22: Mar-27E
A23: OK Historical balance sheet ties to the source | B23: blocking | C23: 0 | D23: Mar-26
... A27: OK Dividend payout inside a plausible band | B27: advisory | C27: 0 | D27: -
A29: Screener vs annual report
A30: line | B30: period | C30: screener | D30: annual report | E30: diff %
A31: shares | B31: Mar-26 | C31: 35.548746 | D31: 53.32323 | E31: 50
A33: Annual-report citations
A34: payables | B34: kb/annual_report/pages/page_0212.md p.212
A35: shares | B35: inputs/shareholding.pdf (BSE, quarter ended 30-09-2026) + kb/annual_report/pages/page_0102.md p.102
A37: Notes
A38: - trade payables supplied from the annual report were netted out of other liabilities so the balance sheet still ties
A39: - built against modeling strategy: revenue_model=consolidated_buildup, modelability=GREEN, decision=APPROVED
A40: - block 'derived' not found in the export
A41: - block 'price' not found in the export
A42: - held at the trailing historical average (no value in assumptions.json or overrides): dep_pct_nb, cwip_pct_sales, other_ca_pct, other_liab_pct
A43: - not in the source at all, held at zero for every year: exceptional
A44: - no actual for 'capex' in Mar-17: set to zero
A46: Valuation
A47: - Scenarios!B4 selects the case. The switched driver rows on Drivers are green links to it.
A48: - Dashboard shows the call; every cell links into the model. Sheets are protected without a password so formulas are not overwritten by accident: blue input cells stay editable.
A49: - DCF discounts the free cash flow built from these statements; Sensitivity re-prices every cell.
...

Sheet Summary
A1: Trent Ltd - Summary
A2: INR cr unless stated | built 2026-10-15 | blue = input, black = formula, green = link to another sheet
A4: Actuals | B4: Mar-17 | C4: Mar-18 | D4: Mar-19 | E4: Mar-20 | F4: Mar-21 | G4: Mar-22 | H4: Mar-23 | I4: Mar-24 | J4: Mar-25 | K4: Mar-26 | L4: Mar-27E | M4: Mar-28E | N4: Mar-29E | O4: Mar-30E | P4: Mar-31E | Q4: Mar-32E | R4: Mar-33E | S4: Mar-34E | T4: Mar-35E | U4: Mar-36E
A5: Operating performance
A6: Revenue | B6: ='Income Statement'!B6 -> 1812.44 | C6: ='Income Statement'!C6 -> 2157.46 | D6: ='Income Statement'!D6 -> 2630.24 | E6: ='Income Statement'!E6 -> 3485.98 | F6: ='Income Statement'!F6 -> 2592.96 | G6: ='Income Statement'!G6 -> 4498.02 | H6: ='Income Statement'!H6 -> 8242.02 | I6: ='Income Statement'!I6 -> 12375.11 | ... U6: ='Income Statement'!U6 -> 69732.375
A7: Revenue growth | B7: =(IFERROR(('Income Statement'!B6)/(0),0)-1) -> -1 | C7: =(IFERROR(('Income Statement'!C6)/('Income Statement'!B6),0)-1) -> 0.19036216 | D7: =(IFERROR(('Income Statement'!D6)/('Income Statement'!C6),0)-1) -> 0.21913732 | E7: =(IFERROR(('Income Statement'!E6)/('Income Statement'!D6),0)-1) -> 0.32534674 | F7: =(IFERROR(('Income Statement'!F6)/('Income Statement'!E6),0)-1) -> -0.25617473 | G7: =(IFERROR(('Income Statement'!G6)/('Income Statement'!F6),0)-1) -> 0.73470474 | H7: =(IFERROR(('Income Statement'!H6)/('Income Statement'!G6),0)-1) -> 0.83236624 | I7: =(IFERROR(('Income Statement'!I6)/('Income Statement'!H6),0)-1) -> 0.50146566 | J7: =(IFERROR(('Income Statement'!J6)/('Income Statement'!I6),0)-1) -> 0.38460264 | ... U7: =(IFERROR(('Income Statement'!U6)/('Income Statement'!T6),0)-1) -> 0.0951
A8: EBITDA | B8: ='Income Statement'!B10 -> 133.53 | C8: ='Income Statement'!C10 -> 208.5 | D8: ='Income Statement'!D10 -> 240.64 | E8: ='Income Statement'!E10 -> 528.97 | F8: ='Income Statement'!F10 -> 113.87 | G8: ='Income Statement'!G10 -> 594.72 | H8: ='Income Statement'!H10 -> 1114.15 | I8: ='Income Statement'!I10 -> 1970.69 | ... U8: ='Income Statement'!U10 -> 13946.475
A9: EBITDA margin | B9: =IFERROR(('Income Statement'!B10)/('Income Statement'!B6),0) -> 0.073674163 | C9: =IFERROR(('Income Statement'!C10)/('Income Statement'!C6),0) -> 0.096641421 | D9: =IFERROR(('Income Statement'!D10)/('Income Statement'!D6),0) -> 0.09148975 | E9: =IFERROR(('Income Statement'!E10)/('Income Statement'!E6),0) -> 0.15174212 | F9: =IFERROR(('Income Statement'!F10)/('Income Statement'!F6),0) -> 0.043915062 | G9: =IFERROR(('Income Statement'!G10)/('Income Statement'!G6),0) -> 0.13221818 | H9: =IFERROR(('Income Statement'!H10)/('Income Statement'!H6),0) -> 0.13517924 | I9: =IFERROR(('Income Statement'!I10)/('Income Statement'!I6),0) -> 0.15924626 | ... U9: =IFERROR(('Income Statement'!U10)/('Income Statement'!U6),0) -> 0.2
A10: EBIT | B10: ='Income Statement'!B12 -> 92.24 | C10: ='Income Statement'!C12 -> 162.97 | D10: ='Income Statement'!D12 -> 188.97 | E10: ='Income Statement'!E12 -> 281.73 | F10: ='Income Statement'!F12 -> -143.43 | G10: ='Income Statement'!G12 -> 283.9 | H10: ='Income Statement'!H12 -> 620.46 | I10: ='Income Statement'!I12 -> 1299.58 | ... U10: ='Income Statement'!U12 -> 10049.049
A11: Profit after tax | B11: ='Income Statement'!B18 -> 84.86 | C11: ='Income Statement'!C18 -> 86.97 | D11: ='Income Statement'!D18 -> 96.96 | E11: ='Income Statement'!E18 -> 122.85 | F11: ='Income Statement'!F18 -> -146.17 | G11: ='Income Statement'!G18 -> 105.83 | H11: ='Income Statement'!H18 -> 444.63 | I11: ='Income Statement'!I18 -> 1486.8 | ... U11: ='Income Statement'!U18 -> 9277.9831
A12: Earnings per share | B12: ='Income Statement'!B19 -> 2.553588 | C12: ='Income Statement'!C19 -> 2.6170816 | D12: ='Income Statement'!D19 -> 2.9176984 | E12: ='Income Statement'!E19 -> 3.4558181 | F12: ='Income Statement'!F19 -> -4.1118187 | G12: ='Income Statement'!G19 -> 2.9770389 | H12: ='Income Statement'!H19 -> 12.507614 | I12: ='Income Statement'!I19 -> 41.82426 | ... U12: ='Income Statement'!U19 -> 173.99514
A13: Cash generation
A14: Free cash flow to the firm | B14: =(((('Income Statement'!B12*(1-Drivers!B22))+'Income Statement'!B11)-Schedules!B7)-Schedules!B12) -> -168.55776 | C14: =(((('Income Statement'!C12*(1-Drivers!C22))+'Income Statement'!C11)-Schedules!C7)-Schedules!C12) -> -5.1681011 | D14: =(((('Income Statement'!D12*(1-Drivers!D22))+'Income Statement'!D11)-Schedules!D7)-Schedules!D12) -> -86.131579 | E14: =(((('Income Statement'!E12*(1-Drivers!E22))+'Income Statement'!E11)-Schedules!E7)-Schedules!E12) -> 238.1835 | F14: =(((('Income Statement'!F12*(1-Drivers!F22))+'Income Statement'!F11)-Schedules!F7)-Schedules!F12) -> -2614.279 | G14: =(((('Income Statement'!G12*(1-Drivers!G22))+'Income Statement'!G11)-Schedules!G7)-Schedules!G12) -> -1744.8885 | H14: =(((('Income Statement'!H12*(1-Drivers!H22))+'Income Statement'!H11)-Schedules!H7)-Schedules!H12) -> 352.92042 | I14: =(((('Income Statement'!I12*(1-Drivers!I22))+'Income Statement'!I11)-Schedules!I7)-Schedules!I12) -> 2884.3074 | ... U14: =(((('Income Statement'!U12*(1-Drivers!U22))+'Income Statement'!U11)-Schedules!U7)-Schedules!U12) -> 6609.172
A15: Free cash flow to equity | B15: =(((('Income Statement'!B18+'Income Statement'!B11)-Schedules!B7)-Schedules!B12)+('Balance Sheet'!B19-0)) -> 246.89 | C15: =(((('Income Statement'!C18+'Income Statement'!C11)-Schedules!C7)-Schedules!C12)+('Balance Sheet'!C19-'Balance Sheet'!B19)) -> -15.15 | D15: =(((('Income Statement'!D18+'Income Statement'!D11)-Schedules!D7)-Schedules!D12)+('Balance Sheet'!D19-'Balance Sheet'!C19)) -> 4.78 | E15: =(((('Income Statement'!E18+'Income Statement'!E11)-Schedules!E7)-Schedules!E12)+('Balance Sheet'!E19-'Balance Sheet'!D19)) -> -43.14 | F15: =(((('Income Statement'!F18+'Income Statement'!F11)-Schedules!F7)-Schedules!F12)+('Balance Sheet'!F19-'Balance Sheet'!E19)) -> 5.8 | G15: =(((('Income Statement'!G18+'Income Statement'!G11)-Schedules!G7)-Schedules!G12)+('Balance Sheet'!G19-'Balance Sheet'!F19)) -> -147.47 | H15: =(((('Income Statement'!H18+'Income Statement'!H11)-Schedules!H7)-Schedules!H12)+('Balance Sheet'!H19-'Balance Sheet'!G19)) -> 36.62 | I15: =(((('Income Statement'!I18+'Income Statement'!I11)-Schedules!I7)-Schedules!I12)+('Balance Sheet'!I19-'Balance Sheet'!H19)) -> 654.03 | J15: =(((('Income Statement'!J18+'Income Statement'!J11)-Schedules!J7)-Schedules!J12)+('Balance Sheet'!J19-'Balance Sheet'!I19)) -> 214.94 | ... U15: =(((('Income Statement'!U18+'Income Statement'!U11)-Schedules!U7)-Schedules!U12)+('Balance Sheet'!U19-'Balance Sheet'!T19)) -> 8249.8777
A16: EBITDA to FCFF conversion | B16: =IFERROR((B14)/('Income Statement'!B10),0) -> -1.2623213 | C16: =IFERROR((C14)/('Income Statement'!C10),0) -> -0.024787055 | D16: =IFERROR((D14)/('Income Statement'!D10),0) -> -0.35792711 | E16: =IFERROR((E14)/('Income Statement'!E10),0) -> 0.45027791 | F16: =IFERROR((F14)/('Income Statement'!F10),0) -> -22.958452 | G16: =IFERROR((G14)/('Income Statement'!G10),0) -> -2.9339664 | H16: =IFERROR((H14)/('Income Statement'!H10),0) -> 0.31676203 | I16: =IFERROR((I14)/('Income Statement'!I10),0) -> 1.4636028 | ... U16: =IFERROR((U14)/('Income Statement'!U10),0) -> 0.47389552
A17: Leverage and returns
A18: Net debt | B18: =(('Balance Sheet'!B19-'Balance Sheet'!B6)-'Balance Sheet'!B12) -> -722.5 | C18: =(('Balance Sheet'!C19-'Balance Sheet'!C6)-'Balance Sheet'!C12) -> -664.26 | D18: =(('Balance Sheet'!D19-'Balance Sheet'!D6)-'Balance Sheet'!D12) -> -442.92 | E18: =(('Balance Sheet'!E19-'Balance Sheet'!E6)-'Balance Sheet'!E12) -> -1276.45 | F18: =(('Balance Sheet'!F19-'Balance Sheet'!F6)-'Balance Sheet'!F12) -> 1394.87 | G18: =(('Balance Sheet'!G19-'Balance Sheet'!G6)-'Balance Sheet'!G12) -> 3355.67 | H18: =(('Balance Sheet'!H19-'Balance Sheet'!H6)-'Balance Sheet'!H12) -> 3267.97 | I18: =(('Balance Sheet'!I19-'Balance Sheet'!I6)-'Balance Sheet'!I12) -> 39.4 | ... U18: =(('Balance Sheet'!U19-'Balance Sheet'!U6)-'Balance Sheet'!U12) -> -35091.385
A19: Net debt / EBITDA | B19: =IFERROR((B18)/('Income Statement'!B10),0) -> -5.4107691 | C19: =IFERROR((C18)/('Income Statement'!C10),0) -> -3.1858993 | D19: =IFERROR((D18)/('Income Statement'!D10),0) -> -1.8405918 | E19: =IFERROR((E18)/('Income Statement'!E10),0) -> -2.4130858 | F19: =IFERROR((F18)/('Income Statement'!F10),0) -> 12.249671 | G19: =IFERROR((G18)/('Income Statement'!G10),0) -> 5.6424368 | H19: =IFERROR((H18)/('Income Statement'!H10),0) -> 2.9331508 | I19: =IFERROR((I18)/('Income Statement'!I10),0) -> 0.019992997 | ... U19: =IFERROR((U18)/('Income Statement'!U10),0) -> -2.5161472
A20: EBIT / interest expense | B20: =IFERROR(('Income Statement'!B12)/('Income Statement'!B14),0) -> 2.0250274 | C20: =IFERROR(('Income Statement'!C12)/('Income Statement'!C14),0) -> 3.722476 | D20: =IFERROR(('Income Statement'!D12)/('Income Statement'!D14),0) -> 3.7316351 | E20: =IFERROR(('Income Statement'!E12)/('Income Statement'!E14),0) -> 1.0697118 | F20: =IFERROR(('Income Statement'!F12)/('Income Statement'!F14),0) -> -0.54998274 | G20: =IFERROR(('Income Statement'!G12)/('Income Statement'!G14),0) -> 0.87396872 | H20: =IFERROR(('Income Statement'!H12)/('Income Statement'!H14),0) -> 1.5170542 | I20: =IFERROR(('Income Statement'!I12)/('Income Statement'!I14),0) -> 3.5347332 | ... U20: =IFERROR(('Income Statement'!U12)/('Income Statement'!U14),0) -> 0
A21: Capital employed | B21: =((('Balance Sheet'!B15+'Balance Sheet'!B16)+'Balance Sheet'!B19)-'Balance Sheet'!B6) -> 1905.15 | C21: =((('Balance Sheet'!C15+'Balance Sheet'!C16)+'Balance Sheet'!C19)-'Balance Sheet'!C6) -> 1953.99 | D21: =((('Balance Sheet'!D15+'Balance Sheet'!D16)+'Balance Sheet'!D19)-'Balance Sheet'!D6) -> 2086.42 | E21: =((('Balance Sheet'!E15+'Balance Sheet'!E16)+'Balance Sheet'!E19)-'Balance Sheet'!E6) -> 2626.1 | F21: =((('Balance Sheet'!F15+'Balance Sheet'!F16)+'Balance Sheet'!F19)-'Balance Sheet'!F6) -> 5195.19 | G21: =((('Balance Sheet'!G15+'Balance Sheet'!G16)+'Balance Sheet'!G19)-'Balance Sheet'!G6) -> 7003.39 | H21: =((('Balance Sheet'!H15+'Balance Sheet'!H16)+'Balance Sheet'!H19)-'Balance Sheet'!H6) -> 6973.33 | I21: =((('Balance Sheet'!I15+'Balance Sheet'!I16)+'Balance Sheet'!I19)-'Balance Sheet'!I6) -> 5523.17 | ... U21: =((('Balance Sheet'!U15+'Balance Sheet'!U16)+'Balance Sheet'!U19)-'Balance Sheet'!U6) -> 21782.776
A22: Post-tax ROCE | B22: =IFERROR((('Income Statement'!B12*(1-Drivers!B22)))/(AVERAGE(0,B21)),0) -> 0.064196769 | C22: =IFERROR((('Income Statement'!C12*(1-Drivers!C22)))/(AVERAGE(B21,C21)),0) -> 0.050084682 | D22: =IFERROR((('Income Statement'!D12*(1-Drivers!D22)))/(AVERAGE(C21,D21)),0) -> 0.053835339 | E22: =IFERROR((('Income Statement'!E12*(1-Drivers!E22)))/(AVERAGE(D21,E21)),0) -> 0.089028165 | F22: =IFERROR((('Income Statement'!F12*(1-Drivers!F22)))/(AVERAGE(E21,F21)),0) -> -0.026174446 | G22: =IFERROR((('Income Statement'!G12*(1-Drivers!G22)))/(AVERAGE(F21,G21)),0) -> 0.044290646 | H22: =IFERROR((('Income Statement'!H12*(1-Drivers!H22)))/(AVERAGE(G21,H21)),0) -> 0.071506107 | I22: =IFERROR((('Income Statement'!I12*(1-Drivers!I22)))/(AVERAGE(H21,I21)),0) -> 0.16099346 | J22: =IFERROR((('Income Statement'!J12*(1-Drivers!J22)))/(AVERAGE(I21,J21)),0) -> 0.22771431 | ... U22: =IFERROR((('Income Statement'!U12*(1-Drivers!U22)))/(AVERAGE(T21,U21)),0) -> 0.35978851
A23: Return on equity | B23: =IFERROR(('Income Statement'!B18)/(AVERAGE(0,Schedules!B24)),0) -> 0.1096602 | C23: =IFERROR(('Income Statement'!C18)/(AVERAGE(Schedules!B24,Schedules!C24)),0) -> 0.055340973 | D23: =IFERROR(('Income Statement'!D18)/(AVERAGE(Schedules!C24,Schedules!D24)),0) -> 0.059817143 | E23: =IFERROR(('Income Statement'!E18)/(AVERAGE(Schedules!D24,Schedules!E24)),0) -> 0.060903061 | F23: =IFERROR(('Income Statement'!F18)/(AVERAGE(Schedules!E24,Schedules!F24)),0) -> -0.062189415 | G23: =IFERROR(('Income Statement'!G18)/(AVERAGE(Schedules!F24,Schedules!G24)),0) -> 0.045255215 | H23: =IFERROR(('Income Statement'!H18)/(AVERAGE(Schedules!G24,Schedules!H24)),0) -> 0.17930473 | I23: =IFERROR(('Income Statement'!I18)/(AVERAGE(Schedules!H24,Schedules!I24)),0) -> 0.44627005 | J23: =IFERROR(('Income Statement'!J18)/(AVERAGE(Schedules!I24,Schedules!J24)),0) -> 0.32461792 | ... U23: =IFERROR(('Income Statement'!U18)/(AVERAGE(Schedules!T24,Schedules!U24)),0) -> 0.18113497

Sheet Scenarios
A1: Trent Ltd - Scenarios
A2: Change the yellow cell: every switched driver, the statements, the checks and the DCF follow
A4: Active scenario (1 Base, 2 Bull, 3 Bear) | B4: 1
A5: Active case | B5: =CHOOSE($B$4,"Base","Bull","Bear") -> Base
A7: INR cr unless stated | B7: Mar-27E | C7: Mar-28E | D7: Mar-29E | E7: Mar-30E | F7: Mar-31E | G7: Mar-32E | H7: Mar-33E | I7: Mar-34E | J7: Mar-35E | K7: Mar-36E
A8: Base case inputs
A9: Revenue growth | B9: 0.1998 | C9: 0.1597 | D9: 0.1564 | E9: 0.1453 | F9: 0.1358 | G9: 0.1232 | H9: 0.1143 | I9: 0.1027 | J9: 0.0981 | K9: 0.0951
A10: EBITDA margin | B10: 0.195 | C10: 0.198 | D10: 0.2 | E10: 0.2 | F10: 0.2 | G10: 0.2 | H10: 0.2 | I10: 0.2 | J10: 0.2 | K10: 0.2
A11: Capex (% sales) | B11: 0.118 | C11: 0.111 | D11: 0.104 | E11: 0.096 | F11: 0.089 | G11: 0.082 | H11: 0.077 | I11: 0.072 | J11: 0.068 | K11: 0.064
A12: Terminal growth | B12: 0.06
A14: Bull case inputs
A15: Revenue growth | B15: 0.2285 | C15: 0.1973 | D15: 0.197 | E15: 0.1858 | F15: 0.1674 | G15: 0.1509 | H15: 0.1385 | I15: 0.1226 | J15: 0.1106 | K15: 0.1072
A16: EBITDA margin | B16: 0.2 | C16: 0.205 | D16: 0.21 | E16: 0.21 | F16: 0.21 | G16: 0.21 | H16: 0.21 | I16: 0.21 | J16: 0.21 | K16: 0.21
A17: Capex (% sales) | B17: 0.12 | C17: 0.117 | D17: 0.11 | E17: 0.101 | F17: 0.092 | G17: 0.085 | H17: 0.078 | I17: 0.072 | J17: 0.068 | K17: 0.065
A18: Terminal growth | B18: 0.065
A19: Zudio returns to ~250 net stores a year from FY28 and Westside to ~45 (area adds 4.0-4.2 mn sq ft a year at peak), sales per sq ft stops falling in FY28 as the FY26-FY27 cohort matures, and EBITDA margin reaches 21% on operating leverage. Revenue CAGR FY26-FY36 about 16%.
A21: Bear case inputs
A22: Revenue growth | B22: 0.148 | C22: 0.0871 | D22: 0.0946 | E22: 0.1032 | F22: 0.1007 | G22: 0.0951 | H22: 0.0902 | I22: 0.0795 | J22: 0.0756 | K22: 0.0739
A23: EBITDA margin | B23: 0.185 | C23: 0.18 | D23: 0.18 | E23: 0.18 | F23: 0.18 | G23: 0.18 | H23: 0.18 | I23: 0.18 | J23: 0.18 | K23: 0.18
A24: Capex (% sales) | B24: 0.106 | C24: 0.097 | D24: 0.094 | E24: 0.089 | F24: 0.084 | G24: 0.08 | H24: 0.075 | I24: 0.07 | J24: 0.066 | K24: 0.063
A25: Terminal growth | B25: 0.05
A26: New-store productivity keeps falling (sales per sq ft -8% FY27, -5% FY28) as value-fashion competition in Tier II/III intensifies, Trent slows openings to ~2.5 mn sq ft a year to protect returns, and EBITDA margin gives back to 18% on negative operating leverage. Revenue CAGR FY26-FY36 about 9.5%.
A28: Active path (feeds the Drivers sheet)
A29: Revenue growth | B29: =CHOOSE(Scenarios!$B$4,B9,B15,B22) -> 0.1998 | C29: =CHOOSE(Scenarios!$B$4,C9,C15,C22) -> 0.1597 | D29: =CHOOSE(Scenarios!$B$4,D9,D15,D22) -> 0.1564 | E29: =CHOOSE(Scenarios!$B$4,E9,E15,E22) -> 0.1453 | F29: =CHOOSE(Scenarios!$B$4,F9,F15,F22) -> 0.1358 | G29: =CHOOSE(Scenarios!$B$4,G9,G15,G22) -> 0.1232 | H29: =CHOOSE(Scenarios!$B$4,H9,H15,H22) -> 0.1143 | I29: =CHOOSE(Scenarios!$B$4,I9,I15,I22) -> 0.1027 | ... K29: =CHOOSE(Scenarios!$B$4,K9,K15,K22) -> 0.0951
A30: EBITDA margin | B30: =CHOOSE(Scenarios!$B$4,B10,B16,B23) -> 0.195 | C30: =CHOOSE(Scenarios!$B$4,C10,C16,C23) -> 0.198 | D30: =CHOOSE(Scenarios!$B$4,D10,D16,D23) -> 0.2 | E30: =CHOOSE(Scenarios!$B$4,E10,E16,E23) -> 0.2 | F30: =CHOOSE(Scenarios!$B$4,F10,F16,F23) -> 0.2 | G30: =CHOOSE(Scenarios!$B$4,G10,G16,G23) -> 0.2 | H30: =CHOOSE(Scenarios!$B$4,H10,H16,H23) -> 0.2 | I30: =CHOOSE(Scenarios!$B$4,I10,I16,I23) -> 0.2 | ... K30: =CHOOSE(Scenarios!$B$4,K10,K16,K23) -> 0.2
A31: Capex (% sales) | B31: =CHOOSE(Scenarios!$B$4,B11,B17,B24) -> 0.118 | C31: =CHOOSE(Scenarios!$B$4,C11,C17,C24) -> 0.111 | D31: =CHOOSE(Scenarios!$B$4,D11,D17,D24) -> 0.104 | E31: =CHOOSE(Scenarios!$B$4,E11,E17,E24) -> 0.096 | F31: =CHOOSE(Scenarios!$B$4,F11,F17,F24) -> 0.089 | G31: =CHOOSE(Scenarios!$B$4,G11,G17,G24) -> 0.082 | H31: =CHOOSE(Scenarios!$B$4,H11,H17,H24) -> 0.077 | I31: =CHOOSE(Scenarios!$B$4,I11,I17,I24) -> 0.072 | ... K31: =CHOOSE(Scenarios!$B$4,K11,K17,K24) -> 0.064
A32: Terminal growth | B32: =CHOOSE(Scenarios!$B$4,B12,B18,B25) -> 0.06
A34: Scenario values (INR per share; recorded with the selector at each case; a range, not weighted)
A35: Case | B35: Value | C35: Target
A36: Base | B36: 772 | C36: 875
A37: Bull | B37: 1041 | C37: 1180
A38: Bear | B38: 483 | C38: 545
A40: Live value, active case (DCF sheet) | B40: =DCF!B45 -> 772.2778
A41: Recorded value, active case | B41: =INDEX(B36:B38,Scenarios!$B$4) -> 772
A42: Difference (must be 0) | B42: =ROUND(B40,0)-B41 -> 0

Sheet Drivers
A1: Trent Ltd - Drivers
A2: INR cr unless stated | built 2026-10-15 | blue = input, black = formula, green = link to another sheet
A4: Actuals | B4: Mar-17 | C4: Mar-18 | D4: Mar-19 | E4: Mar-20 | F4: Mar-21 | G4: Mar-22 | H4: Mar-23 | I4: Mar-24 | J4: Mar-25 | K4: Mar-26 | L4: Mar-27E | M4: Mar-28E | N4: Mar-29E | O4: Mar-30E | P4: Mar-31E | Q4: Mar-32E | R4: Mar-33E | S4: Mar-34E | T4: Mar-35E | U4: Mar-36E
A5: Growth and margins
A6: Revenue growth | B6: =(IFERROR(('Income Statement'!B6)/(0),0)-1) -> -1 | C6: =(IFERROR(('Income Statement'!C6)/('Income Statement'!B6),0)-1) -> 0.19036216 | D6: =(IFERROR(('Income Statement'!D6)/('Income Statement'!C6),0)-1) -> 0.21913732 | E6: =(IFERROR(('Income Statement'!E6)/('Income Statement'!D6),0)-1) -> 0.32534674 | F6: =(IFERROR(('Income Statement'!F6)/('Income Statement'!E6),0)-1) -> -0.25617473 | G6: =(IFERROR(('Income Statement'!G6)/('Income Statement'!F6),0)-1) -> 0.73470474 | H6: =(IFERROR(('Income Statement'!H6)/('Income Statement'!G6),0)-1) -> 0.83236624 | I6: =(IFERROR(('Income Statement'!I6)/('Income Statement'!H6),0)-1) -> 0.50146566 | J6: =(IFERROR(('Income Statement'!J6)/('Income Statement'!I6),0)-1) -> 0.38460264 | K6: =(IFERROR(('Income Statement'!K6)/('Income Statement'!J6),0)-1) -> 0.1715592 | L6: =Scenarios!B29 -> 0.1998 | M6: =Scenarios!C29 -> 0.1597 | N6: =Scenarios!D29 -> 0.1564 | O6: =Scenarios!E29 -> 0.1453 | P6: =Scenarios!F29 -> 0.1358 | Q6: =Scenarios!G29 -> 0.1232 | R6: =Scenarios!H29 -> 0.1143 | S6: =Scenarios!I29 -> 0.1027 | ... U6: =Scenarios!K29 -> 0.0951
A7: Gross margin | B7: =IFERROR(('Income Statement'!B8)/('Income Statement'!B6),0) -> 0.40727969 | C7: =IFERROR(('Income Statement'!C8)/('Income Statement'!C6),0) -> 0.41966016 | D7: =IFERROR(('Income Statement'!D8)/('Income Statement'!D6),0) -> 0.3197693 | E7: =IFERROR(('Income Statement'!E8)/('Income Statement'!E6),0) -> 0.37300845 | F7: =IFERROR(('Income Statement'!F8)/('Income Statement'!F6),0) -> 0.47909339 | G7: =IFERROR(('Income Statement'!G8)/('Income Statement'!G6),0) -> 0.20892971 | H7: =IFERROR(('Income Statement'!H8)/('Income Statement'!H6),0) -> 0.26490957 | I7: =IFERROR(('Income Statement'!I8)/('Income Statement'!I6),0) -> 0.37115226 | ... K7: =IFERROR(('Income Statement'!K8)/('Income Statement'!K6),0) -> 0.37226222 | L7: 0.43 | M7: 0.43 | N7: 0.43 | O7: 0.43 | P7: 0.43 | Q7: 0.43 | R7: 0.43 | S7: 0.43 | T7: 0.43 | U7: 0.43
A8: EBITDA margin | B8: =IFERROR(('Income Statement'!B10)/('Income Statement'!B6),0) -> 0.073674163 | C8: =IFERROR(('Income Statement'!C10)/('Income Statement'!C6),0) -> 0.096641421 | D8: =IFERROR(('Income Statement'!D10)/('Income Statement'!D6),0) -> 0.09148975 | E8: =IFERROR(('Income Statement'!E10)/('Income Statement'!E6),0) -> 0.15174212 | F8: =IFERROR(('Income Statement'!F10)/('Income Statement'!F6),0) -> 0.043915062 | G8: =IFERROR(('Income Statement'!G10)/('Income Statement'!G6),0) -> 0.13221818 | H8: =IFERROR(('Income Statement'!H10)/('Income Statement'!H6),0) -> 0.13517924 | I8: =IFERROR(('Income Statement'!I10)/('Income Statement'!I6),0) -> 0.15924626 | ... K8: =IFERROR(('Income Statement'!K10)/('Income Statement'!K6),0) -> 0.18657521 | L8: =Scenarios!B30 -> 0.195 | M8: =Scenarios!C30 -> 0.198 | N8: =Scenarios!D30 -> 0.2 | O8: =Scenarios!E30 -> 0.2 | P8: =Scenarios!F30 -> 0.2 | Q8: =Scenarios!G30 -> 0.2 | R8: =Scenarios!H30 -> 0.2 | S8: =Scenarios!I30 -> 0.2 | ... U8: =Scenarios!K30 -> 0.2
A9: Other income (% sales) | B9: =IFERROR(('Income Statement'!B13)/('Income Statement'!B6),0) -> 0.044862175 | C9: =IFERROR(('Income Statement'!C13)/('Income Statement'!C6),0) -> 0.012732565 | D9: =IFERROR(('Income Statement'!D13)/('Income Statement'!D6),0) -> 0.01145903 | E9: =IFERROR(('Income Statement'!E13)/('Income Statement'!E6),0) -> 0.042062777 | F9: =IFERROR(('Income Statement'!F13)/('Income Statement'!F6),0) -> 0.076900531 | G9: =IFERROR(('Income Statement'!G13)/('Income Statement'!G6),0) -> 0.033828218 | H9: =IFERROR(('Income Statement'!H13)/('Income Statement'!H6),0) -> 0.041324821 | I9: =IFERROR(('Income Statement'!I13)/('Income Statement'!I6),0) -> 0.079911209 | ... K9: =IFERROR(('Income Statement'!K13)/('Income Statement'!K6),0) -> 0.0042367794 | L9: 0.003 | M9: 0.003 | N9: 0.003 | O9: 0.003 | P9: 0.003 | Q9: 0.003 | R9: 0.003 | S9: 0.003 | T9: 0.003 | U9: 0.003
A10: Capital expenditure and depreciation
A11: Capex (% sales) | B11: =IFERROR((Schedules!B7)/('Income Statement'!B6),0) -> 0 | C11: =IFERROR((Schedules!C7)/('Income Statement'!C6),0) -> 0.050684601 | D11: =IFERROR((Schedules!D7)/('Income Statement'!D6),0) -> 0.0385212 | E11: =IFERROR((Schedules!E7)/('Income Statement'!E6),0) -> 0.66652419 | F11: =IFERROR((Schedules!F7)/('Income Statement'!F6),0) -> 0.22086341 | G11: =IFERROR((Schedules!G7)/('Income Statement'!G6),0) -> 0.43212569 | H11: =IFERROR((Schedules!H7)/('Income Statement'!H6),0) -> 0.040515553 | I11: =IFERROR((Schedules!I7)/('Income Statement'!I6),0) -> -0.11360869 | ... K11: =IFERROR((Schedules!K7)/('Income Statement'!K6),0) -> 0.14868829 | L11: =Scenarios!B31 -> 0.118 | M11: =Scenarios!C31 -> 0.111 | N11: =Scenarios!D31 -> 0.104 | O11: =Scenarios!E31 -> 0.096 | P11: =Scenarios!F31 -> 0.089 | Q11: =Scenarios!G31 -> 0.082 | R11: =Scenarios!H31 -> 0.077 | S11: =Scenarios!I31 -> 0.072 | ... U11: =Scenarios!K31 -> 0.064
A12: Depreciation (% opening net block) | B12: =IFERROR(('Income Statement'!B11)/(0),0) -> 0 | C12: =IFERROR(('Income Statement'!C11)/('Balance Sheet'!B10),0) -> 0.082976436 | D12: =IFERROR(('Income Statement'!D11)/('Balance Sheet'!C10),0) -> 0.084355052 | E12: =IFERROR(('Income Statement'!E11)/('Balance Sheet'!D10),0) -> 0.3733728 | F12: =IFERROR(('Income Statement'!F11)/('Balance Sheet'!E10),0) -> 0.093958947 | G12: =IFERROR(('Income Statement'!G11)/('Balance Sheet'!F10),0) -> 0.10178072 | H12: =IFERROR(('Income Statement'!H11)/('Balance Sheet'!G10),0) -> 0.10533829 | I12: =IFERROR(('Income Statement'!I11)/('Balance Sheet'!H10),0) -> 0.14824772 | J12: =IFERROR(('Income Statement'!J11)/('Balance Sheet'!I10),0) -> 0.36539152 | K12: =IFERROR(('Income Statement'!K11)/('Balance Sheet'!J10),0) -> 0.34945945 | L12: 0.28769956 | M12: 0.28769956 | N12: 0.28769956 | O12: 0.28769956 | P12: 0.28769956 | Q12: 0.28769956 | R12: 0.28769956 | S12: 0.28769956 | T12: 0.28769956 | U12: 0.28769956
A13: Depreciation (% sales) | B13: =IFERROR(('Income Statement'!B11)/('Income Statement'!B6),0) -> 0.022781444 | C13: =IFERROR(('Income Statement'!C11)/('Income Statement'!C6),0) -> 0.02110352 | D13: =IFERROR(('Income Statement'!D11)/('Income Statement'!D6),0) -> 0.019644595 | E13: =IFERROR(('Income Statement'!E11)/('Income Statement'!E6),0) -> 0.070924102 | F13: =IFERROR(('Income Statement'!F11)/('Income Statement'!F6),0) -> 0.099230223 | G13: =IFERROR(('Income Statement'!G11)/('Income Statement'!G6),0) -> 0.069101516 | H13: =IFERROR(('Income Statement'!H11)/('Income Statement'!H6),0) -> 0.059899151 | I13: =IFERROR(('Income Statement'!I11)/('Income Statement'!I6),0) -> 0.054230629 | ... K13: =IFERROR(('Income Statement'!K11)/('Income Statement'!K6),0) -> 0.067807899 | L13: 0.071 | M13: 0.071 | N13: 0.07 | O13: 0.069 | P13: 0.067 | Q13: 0.065 | R13: 0.064 | S13: 0.063 | T13: 0.062 | U13: 0.06
A14: CWIP (% sales) | B14: =IFERROR(('Balance Sheet'!B11)/('Income Statement'!B6),0) -> 0.0030235484 | C14: =IFERROR(('Balance Sheet'!C11)/('Income Statement'!C6),0) -> 0.0044450419 | D14: =IFERROR(('Balance Sheet'!D11)/('Income Statement'!D6),0) -> 0.033145264 | E14: =IFERROR(('Balance Sheet'!E11)/('Income Statement'!E6),0) -> 0.006689654 | F14: =IFERROR(('Balance Sheet'!F11)/('Income Statement'!F6),0) -> 0.041643527 | G14: =IFERROR(('Balance Sheet'!G11)/('Income Statement'!G6),0) -> 0.023281355 | H14: =IFERROR(('Balance Sheet'!H11)/('Income Statement'!H6),0) -> 0.012341635 | I14: =IFERROR(('Balance Sheet'!I11)/('Income Statement'!I6),0) -> 0.018083072 | ... K14: =IFERROR(('Balance Sheet'!K11)/('Income Statement'!K6),0) -> 0.012652553 | L14: 0.013737166 | M14: 0.013737166 | N14: 0.013737166 | O14: 0.013737166 | P14: 0.013737166 | Q14: 0.013737166 | R14: 0.013737166 | S14: 0.013737166 | T14: 0.013737166 | U14: 0.013737166
A15: Working capital
A16: Receivable days | B16: =(IFERROR(('Balance Sheet'!B7)/('Income Statement'!B6),0)*365) -> 1.192205 | C16: =(IFERROR(('Balance Sheet'!C7)/('Income Statement'!C6),0)*365) -> 2.5546244 | D16: =(IFERROR(('Balance Sheet'!D7)/('Income Statement'!D6),0)*365) -> 2.2952658 | E16: =(IFERROR(('Balance Sheet'!E7)/('Income Statement'!E6),0)*365) -> 1.7925519 | F16: =(IFERROR(('Balance Sheet'!F7)/('Income Statement'!F6),0)*365) -> 2.923705 | G16: =(IFERROR(('Balance Sheet'!G7)/('Income Statement'!G6),0)*365) -> 1.4817409 | H16: =(IFERROR(('Balance Sheet'!H7)/('Income Statement'!H6),0)*365) -> 1.5229701 | I16: =(IFERROR(('Balance Sheet'!I7)/('Income Statement'!I6),0)*365) -> 2.4108957 | ... K16: =(IFERROR(('Balance Sheet'!K7)/('Income Statement'!K6),0)*365) -> 0.92985477 | L16: 1 | M16: 1 | N16: 1 | O16: 1 | P16: 1 | Q16: 1 | R16: 1 | S16: 1 | T16: 1 | U16: 1
A17: Inventory days | B17: =(IFERROR(('Balance Sheet'!B8)/('Income Statement'!B7),0)*365) -> 103.75083 | C17: =(IFERROR(('Balance Sheet'!C8)/('Income Statement'!C7),0)*365) -> 100.5072 | D17: =(IFERROR(('Balance Sheet'!D8)/('Income Statement'!D7),0)*365) -> 101.39263 | E17: =(IFERROR(('Balance Sheet'!E8)/('Income Statement'!E7),0)*365) -> 101.50189 | F17: =(IFERROR(('Balance Sheet'!F8)/('Income Statement'!F7),0)*365) -> 115.76479 | G17: =(IFERROR(('Balance Sheet'!G8)/('Income Statement'!G7),0)*365) -> 89.015584 | H17: =(IFERROR(('Balance Sheet'!H8)/('Income Statement'!H7),0)*365) -> 82.002598 | I17: =(IFERROR(('Balance Sheet'!I8)/('Income Statement'!I7),0)*365) -> 74.234387 | ... K17: =(IFERROR(('Balance Sheet'!K8)/('Income Statement'!K7),0)*365) -> 66.301572 | L17: 71 | M17: 71 | N17: 71 | O17: 71 | P17: 71 | Q17: 71 | R17: 71 | S17: 71 | T17: 71 | U17: 71
A18: Payable days | B18: =(IFERROR(('Balance Sheet'!B20)/('Income Statement'!B7),0)*365) -> 0 | C18: =(IFERROR(('Balance Sheet'!C20)/('Income Statement'!C7),0)*365) -> 0 | D18: =(IFERROR(('Balance Sheet'!D20)/('Income Statement'!D7),0)*365) -> 0 | E18: =(IFERROR(('Balance Sheet'!E20)/('Income Statement'!E7),0)*365) -> 0 | F18: =(IFERROR(('Balance Sheet'!F20)/('Income Statement'!F7),0)*365) -> 0 | G18: =(IFERROR(('Balance Sheet'!G20)/('Income Statement'!G7),0)*365) -> 0 | H18: =(IFERROR(('Balance Sheet'!H20)/('Income Statement'!H7),0)*365) -> 0 | I18: =(IFERROR(('Balance Sheet'!I20)/('Income Statement'!I7),0)*365) -> 0 | ... K18: =(IFERROR(('Balance Sheet'!K20)/('Income Statement'!K7),0)*365) -> 35.066977 | L18: 38 | M18: 38 | N18: 38 | O18: 38 | P18: 38 | Q18: 38 | R18: 38 | S18: 38 | T18: 38 | U18: 38
A19: Other current assets (% sales) | B19: =IFERROR(('Balance Sheet'!B9)/('Income Statement'!B6),0) -> 0.1338196 | C19: =IFERROR(('Balance Sheet'!C9)/('Income Statement'!C6),0) -> 0.13820882 | D19: =IFERROR(('Balance Sheet'!D9)/('Income Statement'!D6),0) -> 0.13640961 | E19: =IFERROR(('Balance Sheet'!E9)/('Income Statement'!E6),0) -> 0.15599917 | F19: =IFERROR(('Balance Sheet'!F9)/('Income Statement'!F6),0) -> 0.2098027 | G19: =IFERROR(('Balance Sheet'!G9)/('Income Statement'!G6),0) -> 0.15092418 | H19: =IFERROR(('Balance Sheet'!H9)/('Income Statement'!H6),0) -> 0.10448167 | I19: =IFERROR(('Balance Sheet'!I9)/('Income Statement'!I6),0) -> 0.089695364 | ... K19: =IFERROR(('Balance Sheet'!K9)/('Income Statement'!K6),0) -> 0.097029472 | L19: 0.089806095 | M19: 0.089806095 | N19: 0.089806095 | O19: 0.089806095 | P19: 0.089806095 | Q19: 0.089806095 | R19: 0.089806095 | S19: 0.089806095 | T19: 0.089806095 | U19: 0.089806095
A20: Other liabilities (% sales) | B20: =IFERROR(('Balance Sheet'!B21)/('Income Statement'!B6),0) -> 0.15604379 | C20: =IFERROR(('Balance Sheet'!C21)/('Income Statement'!C6),0) -> 0.16179211 | D20: =IFERROR(('Balance Sheet'!D21)/('Income Statement'!D6),0) -> 0.15896268 | E20: =IFERROR(('Balance Sheet'!E21)/('Income Statement'!E6),0) -> 0.80871663 | F20: =IFERROR(('Balance Sheet'!F21)/('Income Statement'!F6),0) -> 0.17241685 | G20: =IFERROR(('Balance Sheet'!G21)/('Income Statement'!G6),0) -> 0.14154228 | H20: =IFERROR(('Balance Sheet'!H21)/('Income Statement'!H6),0) -> 0.1239866 | I20: =IFERROR(('Balance Sheet'!I21)/('Income Statement'!I6),0) -> 0.10836429 | ... K20: =IFERROR(('Balance Sheet'!K21)/('Income Statement'!K6),0) -> 0.048419838 | L20: 0.067678904 | M20: 0.067678904 | N20: 0.067678904 | O20: 0.067678904 | P20: 0.067678904 | Q20: 0.067678904 | R20: 0.067678904 | S20: 0.067678904 | T20: 0.067678904 | U20: 0.067678904
A21: Financing, tax and distribution
A22: Effective tax rate | B22: =IFERROR(('Income Statement'!B17)/('Income Statement'!B16),0) -> 0.33703125 | C22: =IFERROR(('Income Statement'!C17)/('Income Statement'!C16),0) -> 0.40699577 | D22: =IFERROR(('Income Statement'!D17)/('Income Statement'!D16),0) -> 0.42446726 | E22: =IFERROR(('Income Statement'!E17)/('Income Statement'!E16),0) -> 0.25540942 | F22: =IFERROR(('Income Statement'!F17)/('Income Statement'!F16),0) -> 0.28634899 | G22: =IFERROR(('Income Statement'!G17)/('Income Statement'!G16),0) -> 0.048462507 | H22: =IFERROR(('Income Statement'!H17)/('Income Statement'!H16),0) -> 0.194613 | I22: =IFERROR(('Income Statement'!I17)/('Income Statement'!I16),0) -> 0.22595961 | ... K22: =IFERROR(('Income Statement'!K17)/('Income Statement'!K16),0) -> 0.23109082 | L22: 0.24 | M22: 0.24 | N22: 0.24 | O22: 0.24 | P22: 0.24 | Q22: 0.24 | R22: 0.24 | S22: 0.24 | T22: 0.24 | U22: 0.24
A23: Interest rate on debt | B23: =IFERROR(('Income Statement'!B14)/(AVERAGE(0,'Balance Sheet'!B19)),0) -> 0.2325522 | C23: =IFERROR(('Income Statement'!C14)/(AVERAGE('Balance Sheet'!B19,'Balance Sheet'!C19)),0) -> 0.11180204 | D23: =IFERROR(('Income Statement'!D14)/(AVERAGE('Balance Sheet'!C19,'Balance Sheet'!D19)),0) -> 0.11436702 | E23: =IFERROR(('Income Statement'!E14)/(AVERAGE('Balance Sheet'!D19,'Balance Sheet'!E19)),0) -> 0.66350078 | F23: =IFERROR(('Income Statement'!F14)/(AVERAGE('Balance Sheet'!E19,'Balance Sheet'!F19)),0) -> 0.15982864 | G23: =IFERROR(('Income Statement'!G14)/(AVERAGE('Balance Sheet'!F19,'Balance Sheet'!G19)),0) -> 0.084494843 | H23: =IFERROR(('Income Statement'!H14)/(AVERAGE('Balance Sheet'!G19,'Balance Sheet'!H19)),0) -> 0.08901246 | I23: =IFERROR(('Income Statement'!I14)/(AVERAGE('Balance Sheet'!H19,'Balance Sheet'!I19)),0) -> 0.11827322 | J23: =IFERROR(('Income Statement'!J14)/(AVERAGE('Balance Sheet'!I19,'Balance Sheet'!J19)),0) -> 0.10029623 | K23: =IFERROR(('Income Statement'!K14)/(AVERAGE('Balance Sheet'!J19,'Balance Sheet'!K19)),0) -> 0.097002359 | L23: 0.085 | M23: 0.085 | N23: 0.085 | O23: 0.085 | P23: 0.085 | Q23: 0.085 | R23: 0.085 | S23: 0.085 | T23: 0.085 | U23: 0.085
A24: Yield on cash and investments | B24: =0 -> 0 | C24: =0 -> 0 | D24: =0 -> 0 | E24: =0 -> 0 | F24: =0 -> 0 | G24: =0 -> 0 | H24: =0 -> 0 | I24: =0 -> 0 | ... K24: =0 -> 0 | L24: 0.065 | M24: 0.065 | N24: 0.065 | O24: 0.065 | P24: 0.065 | Q24: 0.065 | R24: 0.065 | S24: 0.065 | T24: 0.065 | U24: 0.065
A25: Term debt growth | B25: =(IFERROR(('Balance Sheet'!B17)/(0),0)-1) -> -1 | C25: =(IFERROR(('Balance Sheet'!C17)/('Balance Sheet'!B17),0)-1) -> -0.0007913412 | D25: =(IFERROR(('Balance Sheet'!D17)/('Balance Sheet'!C17),0)-1) -> 0.26239685 | E25: =(IFERROR(('Balance Sheet'!E17)/('Balance Sheet'!D17),0)-1) -> -0.39341077 | F25: =(IFERROR(('Balance Sheet'!F17)/('Balance Sheet'!E17),0)-1) -> 8.8873357 | G25: =(IFERROR(('Balance Sheet'!G17)/('Balance Sheet'!F17),0)-1) -> 0.59445005 | H25: =(IFERROR(('Balance Sheet'!H17)/('Balance Sheet'!G17),0)-1) -> -0.055280444 | I25: =(IFERROR(('Balance Sheet'!I17)/('Balance Sheet'!H17),0)-1) -> -0.60731742 | J25: =(IFERROR(('Balance Sheet'!J17)/('Balance Sheet'!I17),0)-1) -> 0.27621378 | K25: =(IFERROR(('Balance Sheet'!K17)/('Balance Sheet'!J17),0)-1) -> 0.14485135 | L25: 0 | M25: 0 | N25: 0 | O25: 0 | P25: 0 | Q25: 0 | R25: 0 | S25: 0 | T25: 0 | U25: 0
A26: Scheduled debt repayment | B26: =0 -> 0 | C26: =0 -> 0 | D26: =0 -> 0 | E26: =0 -> 0 | F26: =0 -> 0 | G26: =0 -> 0 | H26: =0 -> 0 | I26: =0 -> 0 | ... K26: =0 -> 0 | L26: 1354.45 | M26: 700 | N26: 506.8 | O26: 0 | P26: 0 | Q26: 0 | R26: 0 | S26: 0 | T26: 0 | U26: 0
A27: Equity issued | B27: =0 -> 0 | C27: =0 -> 0 | D27: =0 -> 0 | E27: =0 -> 0 | F27: =0 -> 0 | G27: =0 -> 0 | H27: =0 -> 0 | I27: =0 -> 0 | ... K27: =0 -> 0 | L27: 0 | M27: 0 | N27: 0 | O27: 0 | P27: 0 | Q27: 0 | R27: 0 | S27: 0 | T27: 0 | U27: 0
A28: Dividend payout | B28: =IFERROR((Schedules!B22)/('Income Statement'!B18),0) -> 0.39158614 | C28: =IFERROR((Schedules!C22)/('Income Statement'!C18),0) -> 0.4393469 | D28: =IFERROR((Schedules!D22)/('Income Statement'!D18),0) -> 0.44554455 | E28: =IFERROR((Schedules!E22)/('Income Statement'!E18),0) -> 0.28937729 | F28: =IFERROR((Schedules!F22)/('Income Statement'!F18),0) -> -0.14592598 | G28: =IFERROR((Schedules!G22)/('Income Statement'!G18),0) -> 0.5711046 | H28: =IFERROR((Schedules!H22)/('Income Statement'!H18),0) -> 0.17589906 | I28: =IFERROR((Schedules!I22)/('Income Statement'!I18),0) -> 0.076513317 | ... K28: =IFERROR((Schedules!K22)/('Income Statement'!K18),0) -> 0.082691245 | L28: 0.08 | M28: 0.08 | N28: 0.08 | O28: 0.08 | P28: 0.08 | Q28: 0.08 | R28: 0.08 | S28: 0.08 | T28: 0.08 | U28: 0.08
A29: Minimum cash balance | B29: =0 -> 0 | C29: =0 -> 0 | D29: =0 -> 0 | E29: =0 -> 0 | F29: =0 -> 0 | G29: =0 -> 0 | H29: =0 -> 0 | I29: =0 -> 0 | ... K29: =0 -> 0 | L29: 600 | M29: 600 | N29: 600 | O29: 600 | P29: 600 | Q29: 600 | R29: 600 | S29: 600 | T29: 600 | U29: 600

Sheet Income Statement
A1: Trent Ltd - Income Statement
A2: INR cr unless stated | built 2026-10-15 | blue = input, black = formula, green = link to another sheet
A4: Actuals | B4: Mar-17 | C4: Mar-18 | D4: Mar-19 | E4: Mar-20 | F4: Mar-21 | G4: Mar-22 | H4: Mar-23 | I4: Mar-24 | J4: Mar-25 | K4: Mar-26 | L4: Mar-27E | M4: Mar-28E | N4: Mar-29E | O4: Mar-30E | P4: Mar-31E | Q4: Mar-32E | R4: Mar-33E | S4: Mar-34E | T4: Mar-35E | U4: Mar-36E
A5: Income statement
A6: Revenue | B6: 1812.44 | C6: 2157.46 | D6: 2630.24 | E6: 3485.98 | F6: 2592.96 | G6: 4498.02 | H6: 8242.02 | I6: 12375.11 | J6: 17134.61 | K6: 20074.21 | L6: =(K6*(1+Drivers!L6)) -> 24085.037 | M6: =(L6*(1+Drivers!M6)) -> 27931.418 | N6: =(M6*(1+Drivers!N6)) -> 32299.891 | O6: =(N6*(1+Drivers!O6)) -> 36993.066 | P6: =(O6*(1+Drivers!P6)) -> 42016.724 | Q6: =(P6*(1+Drivers!Q6)) -> 47193.184 | R6: =(Q6*(1+Drivers!R6)) -> 52587.365 | S6: =(R6*(1+Drivers!S6)) -> 57988.088 | ... U6: =(T6*(1+Drivers!U6)) -> 69732.375
A7: Cost of goods sold | B7: 1074.27 | C7: 1252.06 | D7: 1789.17 | E7: 2185.68 | F7: 1350.69 | G7: 3558.25 | H7: 6058.63 | I7: 7782.06 | J7: 11317.3 | K7: 12601.34 | L7: =(L6*(1-Drivers!L7)) -> 13728.471 | M7: =(M6*(1-Drivers!M7)) -> 15920.908 | N7: =(N6*(1-Drivers!N7)) -> 18410.938 | O7: =(O6*(1-Drivers!O7)) -> 21086.047 | P7: =(P6*(1-Drivers!P7)) -> 23949.533 | Q7: =(Q6*(1-Drivers!Q7)) -> 26900.115 | R7: =(R6*(1-Drivers!R7)) -> 29974.798 | S7: =(S6*(1-Drivers!S7)) -> 33053.21 | ... U7: =(U6*(1-Drivers!U7)) -> 39747.454
A8: Gross profit | B8: =(B6-B7) -> 738.17 | C8: =(C6-C7) -> 905.4 | D8: =(D6-D7) -> 841.07 | E8: =(E6-E7) -> 1300.3 | F8: =(F6-F7) -> 1242.27 | G8: =(G6-G7) -> 939.77 | H8: =(H6-H7) -> 2183.39 | I8: =(I6-I7) -> 4593.05 | ... U8: =(U6-U7) -> 29984.921
A9: Operating expenses | B9: =(B8-B10) -> 604.64 | C9: =(C8-C10) -> 696.9 | D9: =(D8-D10) -> 600.43 | E9: =(E8-E10) -> 771.33 | F9: =(F8-F10) -> 1128.4 | G9: =(G8-G10) -> 345.05 | H9: =(H8-H10) -> 1069.24 | I9: =(I8-I10) -> 2622.36 | ... U9: =(U8-U10) -> 16038.446
A10: EBITDA | B10: 133.53 | C10: 208.5 | D10: 240.64 | E10: 528.97 | F10: 113.87 | G10: 594.72 | H10: 1114.15 | I10: 1970.69 | J10: 2819.96 | K10: 3745.35 | L10: =(L6*Drivers!L8) -> 4696.5822 | M10: =(M6*Drivers!M8) -> 5530.4207 | N10: =(N6*Drivers!N8) -> 6459.9783 | O10: =(O6*Drivers!O8) -> 7398.6131 | P10: =(P6*Drivers!P8) -> 8403.3448 | Q10: =(Q6*Drivers!Q8) -> 9438.6368 | R10: =(R6*Drivers!R8) -> 10517.473 | S10: =(S6*Drivers!S8) -> 11597.618 | ... U10: =(U6*Drivers!U8) -> 13946.475
A11: Depreciation and amortisation | B11: 41.29 | C11: 45.53 | D11: 51.67 | E11: 247.24 | F11: 257.3 | G11: 310.82 | H11: 493.69 | I11: 671.11 | J11: 895.18 | K11: 1361.19 | L11: =MIN((Drivers!L12*'Balance Sheet'!K10),('Balance Sheet'!K10+Schedules!L7)) -> 1587.7391 | M11: =MIN((Drivers!M12*'Balance Sheet'!L10),('Balance Sheet'!L10+Schedules!M7)) -> 1948.5993 | N11: =MIN((Drivers!N12*'Balance Sheet'!M10),('Balance Sheet'!M10+Schedules!N7)) -> 2279.9682 | O11: =MIN((Drivers!O12*'Balance Sheet'!N10),('Balance Sheet'!N10+Schedules!O7)) -> 2590.4595 | P11: =MIN((Drivers!P12*'Balance Sheet'!O10),('Balance Sheet'!O10+Schedules!P7)) -> 2866.9027 | Q11: =MIN((Drivers!Q12*'Balance Sheet'!P10),('Balance Sheet'!P10+Schedules!Q7)) -> 3117.9453 | R11: =MIN((Drivers!R12*'Balance Sheet'!Q10),('Balance Sheet'!Q10+Schedules!R7)) -> 3334.2654 | S11: =MIN((Drivers!S12*'Balance Sheet'!R10),('Balance Sheet'!R10+Schedules!S7)) -> 3539.9596 | ... U11: =MIN((Drivers!U12*'Balance Sheet'!T10),('Balance Sheet'!T10+Schedules!U7)) -> 3897.4258
A12: EBIT | B12: =(B10-B11) -> 92.24 | C12: =(C10-C11) -> 162.97 | D12: =(D10-D11) -> 188.97 | E12: =(E10-E11) -> 281.73 | F12: =(F10-F11) -> -143.43 | G12: =(G10-G11) -> 283.9 | H12: =(H10-H11) -> 620.46 | I12: =(I10-I11) -> 1299.58 | ... U12: =(U10-U11) -> 10049.049
A13: Other income | B13: 81.31 | C13: 27.47 | D13: 30.14 | E13: 146.63 | F13: 199.4 | G13: 152.16 | H13: 340.6 | I13: 988.91 | J13: 305.06 | K13: 85.05 | L13: =((L6*Drivers!L9)+(Drivers!L24*AVERAGE('Balance Sheet'!K6,'Balance Sheet'!L6))) -> 100.95261 | M13: =((M6*Drivers!M9)+(Drivers!M24*AVERAGE('Balance Sheet'!L6,'Balance Sheet'!M6))) -> 122.79425 | N13: =((N6*Drivers!N9)+(Drivers!N24*AVERAGE('Balance Sheet'!M6,'Balance Sheet'!N6))) -> 159.27949 | O13: =((O6*Drivers!O9)+(Drivers!O24*AVERAGE('Balance Sheet'!N6,'Balance Sheet'!O6))) -> 267.09164 | P13: =((P6*Drivers!P9)+(Drivers!P24*AVERAGE('Balance Sheet'!O6,'Balance Sheet'!P6))) -> 445.37031 | Q13: =((Q6*Drivers!Q9)+(Drivers!Q24*AVERAGE('Balance Sheet'!P6,'Balance Sheet'!Q6))) -> 673.08001 | R13: =((R6*Drivers!R9)+(Drivers!R24*AVERAGE('Balance Sheet'!Q6,'Balance Sheet'!R6))) -> 954.47008 | S13: =((S6*Drivers!S9)+(Drivers!S24*AVERAGE('Balance Sheet'!R6,'Balance Sheet'!S6))) -> 1292.564 | ... U13: =((U6*Drivers!U9)+(Drivers!U24*AVERAGE('Balance Sheet'!T6,'Balance Sheet'!U6))) -> 2158.8233
A14: Interest expense | B14: 45.55 | C14: 43.78 | D14: 50.64 | E14: 263.37 | F14: 260.79 | G14: 324.84 | H14: 408.99 | I14: 367.66 | J14: 200.1 | K14: 232.73 | L14: =(Drivers!L23*AVERAGE('Balance Sheet'!K19,'Balance Sheet'!L19)) -> 186.6479 | M14: =(Drivers!M23*AVERAGE('Balance Sheet'!L19,'Balance Sheet'!M19)) -> 112.53324 | N14: =(Drivers!N23*AVERAGE('Balance Sheet'!M19,'Balance Sheet'!N19)) -> 34.738466 | O14: =(Drivers!O23*AVERAGE('Balance Sheet'!N19,'Balance Sheet'!O19)) -> 0 | P14: =(Drivers!P23*AVERAGE('Balance Sheet'!O19,'Balance Sheet'!P19)) -> 0 | Q14: =(Drivers!Q23*AVERAGE('Balance Sheet'!P19,'Balance Sheet'!Q19)) -> 0 | R14: =(Drivers!R23*AVERAGE('Balance Sheet'!Q19,'Balance Sheet'!R19)) -> 0 | S14: =(Drivers!S23*AVERAGE('Balance Sheet'!R19,'Balance Sheet'!S19)) -> 0 | ... U14: =(Drivers!U23*AVERAGE('Balance Sheet'!T19,'Balance Sheet'!U19)) -> 0
A15: Exceptional items | B15: 0 | C15: 0 | D15: 0 | E15: 0 | F15: 0 | G15: 0 | H15: 0 | I15: 0 | J15: 0 | K15: 0 | L15: =0 -> 0 | M15: =0 -> 0 | N15: =0 -> 0 | O15: =0 -> 0 | P15: =0 -> 0 | Q15: =0 -> 0 | R15: =0 -> 0 | S15: =0 -> 0 | ... U15: =0 -> 0
A16: Profit before tax | B16: 128 | C16: 146.66 | D16: 168.47 | E16: 164.99 | F16: -204.82 | G16: 111.22 | H16: 552.07 | I16: 1920.83 | J16: 2029.74 | K16: 2236.48 | L16: =(((L12+L13)-L14)+L15) -> 3023.1479 | M16: =(((M12+M13)-M14)+M15) -> 3592.0824 | N16: =(((N12+N13)-N14)+N15) -> 4304.5511 | O16: =(((O12+O13)-O14)+O15) -> 5075.2453 | P16: =(((P12+P13)-P14)+P15) -> 5981.8123 | Q16: =(((Q12+Q13)-Q14)+Q15) -> 6993.7716 | R16: =(((R12+R13)-R14)+R15) -> 8137.6777 | S16: =(((S12+S13)-S14)+S15) -> 9350.2219 | ... U16: =(((U12+U13)-U14)+U15) -> 12207.873
A17: Tax | B17: 43.14 | C17: 59.69 | D17: 71.51 | E17: 42.14 | F17: -58.65 | G17: 5.39 | H17: 107.44 | I17: 434.03 | J17: 483.02 | K17: 516.83 | L17: =(L16*Drivers!L22) -> 725.55549 | M17: =(M16*Drivers!M22) -> 862.09977 | N17: =(N16*Drivers!N22) -> 1033.0923 | O17: =(O16*Drivers!O22) -> 1218.0589 | P17: =(P16*Drivers!P22) -> 1435.635 | Q17: =(Q16*Drivers!Q22) -> 1678.5052 | R17: =(R16*Drivers!R22) -> 1953.0427 | S17: =(S16*Drivers!S22) -> 2244.0533 | ... U17: =(U16*Drivers!U22) -> 2929.8894
A18: Profit after tax | B18: 84.86 | C18: 86.97 | D18: 96.96 | E18: 122.85 | F18: -146.17 | G18: 105.83 | H18: 444.63 | I18: 1486.8 | J18: 1546.72 | K18: 1719.65 | L18: =(L16-L17) -> 2297.5924 | M18: =(M16-M17) -> 2729.9826 | N18: =(N16-N17) -> 3271.4588 | O18: =(O16-O17) -> 3857.1864 | P18: =(P16-P17) -> 4546.1774 | Q18: =(Q16-Q17) -> 5315.2664 | R18: =(R16-R17) -> 6184.6351 | S18: =(S16-S17) -> 7106.1687 | ... U18: =(U16-U17) -> 9277.9831
A19: Earnings per share | B19: =IFERROR((B18)/(Schedules!B23),0) -> 2.553588 | C19: =IFERROR((C18)/(Schedules!C23),0) -> 2.6170816 | D19: =IFERROR((D18)/(Schedules!D23),0) -> 2.9176984 | E19: =IFERROR((E18)/(Schedules!E23),0) -> 3.4558181 | F19: =IFERROR((F18)/(Schedules!F23),0) -> -4.1118187 | G19: =IFERROR((G18)/(Schedules!G23),0) -> 2.9770389 | H19: =IFERROR((H18)/(Schedules!H23),0) -> 12.507614 | I19: =IFERROR((I18)/(Schedules!I23),0) -> 41.82426 | ... U19: =IFERROR((U18)/(Schedules!U23),0) -> 173.99514

Sheet Balance Sheet
A1: Trent Ltd - Balance Sheet
A2: INR cr unless stated | built 2026-10-15 | blue = input, black = formula, green = link to another sheet
A4: Actuals | B4: Mar-17 | C4: Mar-18 | D4: Mar-19 | E4: Mar-20 | F4: Mar-21 | G4: Mar-22 | H4: Mar-23 | I4: Mar-24 | J4: Mar-25 | K4: Mar-26 | L4: Mar-27E | M4: Mar-28E | N4: Mar-29E | O4: Mar-30E | P4: Mar-31E | Q4: Mar-32E | R4: Mar-33E | S4: Mar-34E | T4: Mar-35E | U4: Mar-36E
A5: Assets
A6: Cash and bank | B6: 34.28 | C6: 32.81 | D6: 54.23 | E6: 61.41 | F6: 81.47 | G6: 85.97 | H6: 86.3 | I6: 297.56 | J6: 339.84 | K6: 283 | L6: =(K6+'Cash Flow'!L21) -> 600 | M6: =(L6+'Cash Flow'!M21) -> 600 | N6: =(M6+'Cash Flow'!N21) -> 1319.379 | O6: =(N6+'Cash Flow'!O21) -> 3484.0808 | P6: =(O6+'Cash Flow'!P21) -> 6341.1542 | Q6: =(P6+'Cash Flow'!Q21) -> 10012.706 | R6: =(Q6+'Cash Flow'!R21) -> 14501.386 | S6: =(R6+'Cash Flow'!S21) -> 19917.066 | ... U6: =(T6+'Cash Flow'!U21) -> 33706.475
A7: Trade receivables | B7: 5.92 | C7: 15.1 | D7: 16.54 | E7: 17.12 | F7: 20.77 | G7: 18.26 | H7: 34.39 | I7: 81.74 | J7: 62.95 | K7: 51.14 | L7: =(IFERROR((Drivers!L16)/(365),0)*'Income Statement'!L6) -> 65.986403 | M7: =(IFERROR((Drivers!M16)/(365),0)*'Income Statement'!M6) -> 76.524432 | N7: =(IFERROR((Drivers!N16)/(365),0)*'Income Statement'!N6) -> 88.492853 | O7: =(IFERROR((Drivers!O16)/(365),0)*'Income Statement'!O6) -> 101.35086 | P7: =(IFERROR((Drivers!P16)/(365),0)*'Income Statement'!P6) -> 115.11431 | Q7: =(IFERROR((Drivers!Q16)/(365),0)*'Income Statement'!Q6) -> 129.2964 | R7: =(IFERROR((Drivers!R16)/(365),0)*'Income Statement'!R6) -> 144.07497 | S7: =(IFERROR((Drivers!S16)/(365),0)*'Income Statement'!S6) -> 158.87147 | ... U7: =(IFERROR((Drivers!U16)/(365),0)*'Income Statement'!U6) -> 191.0476
A8: Inventories | B8: 305.36 | C8: 344.77 | D8: 497.01 | E8: 607.81 | F8: 428.39 | G8: 867.78 | H8: 1361.16 | I8: 1582.73 | J8: 2045.05 | K8: 2289.01 | L8: =(IFERROR((Drivers!L17)/(365),0)*'Income Statement'!L7) -> 2670.4697 | M8: =(IFERROR((Drivers!M17)/(365),0)*'Income Statement'!M7) -> 3096.9438 | N8: =(IFERROR((Drivers!N17)/(365),0)*'Income Statement'!N7) -> 3581.3058 | O8: =(IFERROR((Drivers!O17)/(365),0)*'Income Statement'!O7) -> 4101.6695 | P8: =(IFERROR((Drivers!P17)/(365),0)*'Income Statement'!P7) -> 4658.6762 | Q8: =(IFERROR((Drivers!Q17)/(365),0)*'Income Statement'!Q7) -> 5232.6251 | R8: =(IFERROR((Drivers!R17)/(365),0)*'Income Statement'!R7) -> 5830.7142 | S8: =(IFERROR((Drivers!S17)/(365),0)*'Income Statement'!S7) -> 6429.5285 | ... U8: =(IFERROR((Drivers!U17)/(365),0)*'Income Statement'!U7) -> 7731.6965
A9: Other current assets | B9: 242.54 | C9: 298.18 | D9: 358.79 | E9: 543.81 | F9: 544.01 | G9: 678.86 | H9: 861.14 | I9: 1109.99 | J9: 1416.92 | K9: 1947.79 | L9: =('Income Statement'!L6*Drivers!L19) -> 2162.9831 | M9: =('Income Statement'!M6*Drivers!M19) -> 2508.4115 | N9: =('Income Statement'!N6*Drivers!N19) -> 2900.7271 | O9: =('Income Statement'!O6*Drivers!O19) -> 3322.2028 | P9: =('Income Statement'!P6*Drivers!P19) -> 3773.3579 | Q9: =('Income Statement'!Q6*Drivers!Q19) -> 4238.2356 | R9: =('Income Statement'!R6*Drivers!R19) -> 4722.6659 | S9: =('Income Statement'!S6*Drivers!S19) -> 5207.6837 | ... U9: =('Income Statement'!U6*Drivers!U19) -> 6262.3923
A10: Net fixed assets | B10: 548.71 | C10: 612.53 | D10: 662.18 | E10: 2738.43 | F10: 3053.82 | G10: 4686.71 | H10: 4526.95 | I10: 2449.92 | J10: 3895.13 | K10: 5518.74 | L10: =((K10+Schedules!L7)-'Income Statement'!L11) -> 6773.0353 | M10: =((L10+Schedules!M7)-'Income Statement'!M11) -> 7924.8233 | N10: =((M10+Schedules!N7)-'Income Statement'!N11) -> 9004.0438 | O10: =((N10+Schedules!O7)-'Income Statement'!O11) -> 9964.9186 | P10: =((O10+Schedules!P7)-'Income Statement'!P11) -> 10837.504 | Q10: =((P10+Schedules!Q7)-'Income Statement'!Q11) -> 11589.4 | R10: =((Q10+Schedules!R7)-'Income Statement'!R11) -> 12304.362 | S10: =((R10+Schedules!S7)-'Income Statement'!S11) -> 12939.545 | ... U10: =((T10+Schedules!U7)-'Income Statement'!U11) -> 14112.306
A11: Capital work in progress | B11: 5.48 | C11: 9.59 | D11: 87.18 | E11: 23.32 | F11: 107.98 | G11: 104.72 | H11: 101.72 | I11: 223.78 | J11: 179.5 | K11: 253.99 | L11: =('Income Statement'!L6*Drivers!L14) -> 330.86015 | M11: =('Income Statement'!M6*Drivers!M14) -> 383.69851 | N11: =('Income Statement'!N6*Drivers!N14) -> 443.70896 | O11: =('Income Statement'!O6*Drivers!O14) -> 508.17987 | P11: =('Income Statement'!P6*Drivers!P14) -> 577.1907 | Q11: =('Income Statement'!Q6*Drivers!Q14) -> 648.3006 | R11: =('Income Statement'!R6*Drivers!R14) -> 722.40135 | S11: =('Income Statement'!S6*Drivers!S14) -> 796.59197 | ... U11: =('Income Statement'!U6*Drivers!U14) -> 957.9252
A12: Investments | B12: 1079.96 | C12: 1022.88 | D12: 882.83 | E12: 1514.78 | F12: 1487.29 | G12: 1283.72 | H12: 1109.87 | I12: 1416.03 | J12: 1480.25 | K12: 1384.91 | L12: =K12 -> 1384.91 | M12: =L12 -> 1384.91 | N12: =M12 -> 1384.91 | O12: =N12 -> 1384.91 | P12: =O12 -> 1384.91 | Q12: =P12 -> 1384.91 | R12: =Q12 -> 1384.91 | S12: =R12 -> 1384.91 | ... U12: =T12 -> 1384.91
A13: Total assets | B13: =((((((B6+B7)+B8)+B9)+B10)+B11)+B12) -> 2222.25 | C13: =((((((C6+C7)+C8)+C9)+C10)+C11)+C12) -> 2335.86 | D13: =((((((D6+D7)+D8)+D9)+D10)+D11)+D12) -> 2558.76 | E13: =((((((E6+E7)+E8)+E9)+E10)+E11)+E12) -> 5506.68 | F13: =((((((F6+F7)+F8)+F9)+F10)+F11)+F12) -> 5723.73 | G13: =((((((G6+G7)+G8)+G9)+G10)+G11)+G12) -> 7726.02 | H13: =((((((H6+H7)+H8)+H9)+H10)+H11)+H12) -> 8081.53 | I13: =((((((I6+I7)+I8)+I9)+I10)+I11)+I12) -> 7161.75 | ... U13: =((((((U6+U7)+U8)+U9)+U10)+U11)+U12) -> 64346.753
A14: Liabilities and equity
A15: Share capital | B15: 33.23 | C15: 33.23 | D15: 33.23 | E15: 35.55 | F15: 35.55 | G15: 35.55 | H15: 35.55 | I15: 35.55 | J15: 35.55 | K15: 35.55 | L15: =K15 -> 35.55 | M15: =L15 -> 35.55 | N15: =M15 -> 35.55 | O15: =N15 -> 35.55 | P15: =O15 -> 35.55 | Q15: =P15 -> 35.55 | R15: =Q15 -> 35.55 | S15: =R15 -> 35.55 | ... U15: =T15 -> 35.55
A16: Reserves and surplus | B16: 1514.46 | C16: 1562.14 | D16: 1613.28 | E16: 2352.22 | F16: 2277.48 | G16: 2328.45 | H16: 2559.94 | I16: 4032.19 | J16: 5426.19 | K16: 6949.13 | L16: =(((K16+'Income Statement'!L18)-Schedules!L22)+Drivers!L27) -> 9062.915 | M16: =(((L16+'Income Statement'!M18)-Schedules!M22)+Drivers!M27) -> 11574.499 | N16: =(((M16+'Income Statement'!N18)-Schedules!N22)+Drivers!N27) -> 14584.241 | O16: =(((N16+'Income Statement'!O18)-Schedules!O22)+Drivers!O27) -> 18132.853 | P16: =(((O16+'Income Statement'!P18)-Schedules!P22)+Drivers!P27) -> 22315.336 | Q16: =(((P16+'Income Statement'!Q18)-Schedules!Q22)+Drivers!Q27) -> 27205.381 | R16: =(((Q16+'Income Statement'!R18)-Schedules!R22)+Drivers!R27) -> 32895.245 | S16: =(((R16+'Income Statement'!S18)-Schedules!S22)+Drivers!S27) -> 39432.92 | ... U16: =(((T16+'Income Statement'!U18)-Schedules!U22)+Drivers!U27) -> 55453.701
A17: Term borrowings | B17: 391.74 | C17: 391.43 | D17: 494.14 | E17: 299.74 | F17: 2963.63 | G17: 4725.36 | H17: 4464.14 | I17: 1752.99 | J17: 2237.19 | K17: 2561.25 | L17: =MAX(((K17*(1+Drivers!L25))-Drivers!L26),0) -> 1206.8 | M17: =MAX(((L17*(1+Drivers!M25))-Drivers!M26),0) -> 506.8 | N17: =MAX(((M17*(1+Drivers!N25))-Drivers!N26),0) -> 0 | O17: =MAX(((N17*(1+Drivers!O25))-Drivers!O26),0) -> 0 | P17: =MAX(((O17*(1+Drivers!P25))-Drivers!P26),0) -> 0 | Q17: =MAX(((P17*(1+Drivers!Q25))-Drivers!Q26),0) -> 0 | R17: =MAX(((Q17*(1+Drivers!R25))-Drivers!R26),0) -> 0 | S17: =MAX(((R17*(1+Drivers!S25))-Drivers!S26),0) -> 0 | ... U17: =MAX(((T17*(1+Drivers!U25))-Drivers!U26),0) -> 0
A18: Revolver / short-term plug | B18: 0 | C18: 0 | D18: 0 | E18: 0 | F18: 0 | G18: 0 | H18: 0 | I18: 0 | J18: 0 | K18: 0 | L18: =((K18+Schedules!L18)-Schedules!L19) -> 623.66532 | M18: =((L18+Schedules!M18)-Schedules!M19) -> 310.57567 | N18: =((M18+Schedules!N18)-Schedules!N19) -> 0 | O18: =((N18+Schedules!O18)-Schedules!O19) -> 0 | P18: =((O18+Schedules!P18)-Schedules!P19) -> 0 | Q18: =((P18+Schedules!Q18)-Schedules!Q19) -> 0 | R18: =((Q18+Schedules!R18)-Schedules!R19) -> 0 | S18: =((R18+Schedules!S18)-Schedules!S19) -> 0 | ... U18: =((T18+Schedules!U18)-Schedules!U19) -> 0
A19: Total debt | B19: =(B17+B18) -> 391.74 | C19: =(C17+C18) -> 391.43 | D19: =(D17+D18) -> 494.14 | E19: =(E17+E18) -> 299.74 | F19: =(F17+F18) -> 2963.63 | G19: =(G17+G18) -> 4725.36 | H19: =(H17+H18) -> 4464.14 | I19: =(I17+I18) -> 1752.99 | ... U19: =(U17+U18) -> 0
A20: Trade payables | B20: 0 | C20: 0 | D20: 0 | E20: 0 | F20: 0 | G20: 0 | H20: 0 | I20: 0 | J20: 928.19 | K20: 1210.66 | L20: =(IFERROR((Drivers!L18)/(365),0)*'Income Statement'!L7) -> 1429.2655 | M20: =(IFERROR((Drivers!M18)/(365),0)*'Income Statement'!M7) -> 1657.5192 | N20: =(IFERROR((Drivers!N18)/(365),0)*'Income Statement'!N7) -> 1916.7552 | O20: =(IFERROR((Drivers!O18)/(365),0)*'Income Statement'!O7) -> 2195.2597 | P20: =(IFERROR((Drivers!P18)/(365),0)*'Income Statement'!P7) -> 2493.376 | Q20: =(IFERROR((Drivers!Q18)/(365),0)*'Income Statement'!Q7) -> 2800.5599 | R20: =(IFERROR((Drivers!R18)/(365),0)*'Income Statement'!R7) -> 3120.6639 | S20: =(IFERROR((Drivers!S18)/(365),0)*'Income Statement'!S7) -> 3441.1561 | ... U20: =(IFERROR((Drivers!U18)/(365),0)*'Income Statement'!U7) -> 4138.0911
A21: Other liabilities | B21: 282.82 | C21: 349.06 | D21: 418.11 | E21: 2819.17 | F21: 447.07 | G21: 636.66 | H21: 1021.9 | I21: 1341.02 | J21: 792.52 | K21: 971.99 | L21: =('Income Statement'!L6*Drivers!L20) -> 1630.0489 | M21: =('Income Statement'!M6*Drivers!M20) -> 1890.3677 | N21: =('Income Statement'!N6*Drivers!N20) -> 2186.0212 | O21: =('Income Statement'!O6*Drivers!O20) -> 2503.6501 | P21: =('Income Statement'!P6*Drivers!P20) -> 2843.6458 | Q21: =('Income Statement'!Q6*Drivers!Q20) -> 3193.983 | R21: =('Income Statement'!R6*Drivers!R20) -> 3559.0552 | S21: =('Income Statement'!S6*Drivers!S20) -> 3924.5702 | ... U21: =('Income Statement'!U6*Drivers!U20) -> 4719.4107
A22: Total liabilities and equity | B22: =((((B15+B16)+B19)+B20)+B21) -> 2222.25 | C22: =((((C15+C16)+C19)+C20)+C21) -> 2335.86 | D22: =((((D15+D16)+D19)+D20)+D21) -> 2558.76 | E22: =((((E15+E16)+E19)+E20)+E21) -> 5506.68 | F22: =((((F15+F16)+F19)+F20)+F21) -> 5723.73 | G22: =((((G15+G16)+G19)+G20)+G21) -> 7726.02 | H22: =((((H15+H16)+H19)+H20)+H21) -> 8081.53 | I22: =((((I15+I16)+I19)+I20)+I21) -> 7161.75 | ... U22: =((((U15+U16)+U19)+U20)+U21) -> 64346.753

Sheet Cash Flow
A1: Trent Ltd - Cash Flow
A2: INR cr unless stated | built 2026-10-15 | blue = input, black = formula, green = link to another sheet
A4: Actuals | B4: Mar-17 | C4: Mar-18 | D4: Mar-19 | E4: Mar-20 | F4: Mar-21 | G4: Mar-22 | H4: Mar-23 | I4: Mar-24 | J4: Mar-25 | K4: Mar-26 | L4: Mar-27E | M4: Mar-28E | N4: Mar-29E | O4: Mar-30E | P4: Mar-31E | Q4: Mar-32E | R4: Mar-33E | S4: Mar-34E | T4: Mar-35E | U4: Mar-36E
A5: Operating
A6: Profit after tax | B6: ='Income Statement'!B18 -> 84.86 | C6: ='Income Statement'!C18 -> 86.97 | D6: ='Income Statement'!D18 -> 96.96 | E6: ='Income Statement'!E18 -> 122.85 | F6: ='Income Statement'!F18 -> -146.17 | G6: ='Income Statement'!G18 -> 105.83 | H6: ='Income Statement'!H18 -> 444.63 | I6: ='Income Statement'!I18 -> 1486.8 | ... U6: ='Income Statement'!U18 -> 9277.9831
A7: Depreciation and amortisation | B7: ='Income Statement'!B11 -> 41.29 | C7: ='Income Statement'!C11 -> 45.53 | D7: ='Income Statement'!D11 -> 51.67 | E7: ='Income Statement'!E11 -> 247.24 | F7: ='Income Statement'!F11 -> 257.3 | G7: ='Income Statement'!G11 -> 310.82 | H7: ='Income Statement'!H11 -> 493.69 | I7: ='Income Statement'!I11 -> 671.11 | ... U7: ='Income Statement'!U11 -> 3897.4258
A8: (Increase)/decrease in net operating assets | B8: =-(Schedules!B12) -> -271 | C8: =-(Schedules!C12) -> -37.99 | D8: =-(Schedules!D12) -> -145.24 | E8: =-(Schedules!E12) -> 2104.66 | F8: =-(Schedules!F12) -> -2196.53 | G8: =-(Schedules!G12) -> -382.14 | H8: =-(Schedules!H12) -> -306.55 | I8: =-(Schedules!I12) -> -198.65 | ... U8: =-(Schedules!U12) -> -462.65916
A9: Cash from operations | B9: =((B6+B7)+B8) -> -144.85 | C9: =((C6+C7)+C8) -> 94.51 | D9: =((D6+D7)+D8) -> 3.39 | E9: =((E6+E7)+E8) -> 2474.75 | F9: =((F6+F7)+F8) -> -2085.4 | G9: =((G6+G7)+G8) -> 34.51 | H9: =((H6+H7)+H8) -> 631.77 | I9: =((I6+I7)+I8) -> 1959.26 | ... U9: =((U6+U7)+U8) -> 12712.75
A10: Investing
